<?xml version="1.0" encoding="utf-8"?>
<mujoco model="reacher">
	<compiler angle="degree" inertiafromgeom="true"/>
	<default>
		<joint armature="1" damping="1" limited="true"/>
		<geom contype="0" friction="1 0.1 0.1" rgba="0.7 0.7 0 1"/>
	</default>
	<option gravity="0 0 -9.81" integrator="RK4" timestep="0.01"/>
	<worldbody>
		<light cutoff="100" diffuse="1 1 1" dir="0 0 -1.3" directional="true" exponent="1" pos="0 0 1.3" specular="0.1 0.1 0.1"/>
		<geom conaffinity="1" condim="3" material="MatPlane" name="floor" pos="0 0 0" rgba="0.8 0.9 0.8 1" size="40 40 40" type="plane"/>
		<geom conaffinity="0" fromto="-3 -3 0.1 3 -3 0.1" name="sideS" rgba="0.3 0.1 0.3 1" size="0.2" type="capsule"/>
		<geom conaffinity="0" fromto="3 -3 0.1 3 3 0.1" name="sideE" rgba="0.3 0.1 0.3 1" size="0.2" type="capsule"/>
		<geom conaffinity="0" fromto="-3 3 0.1 3 3 0.1" name="sideN" rgba="0.3 0.1 0.3 1" size="0.2" type="capsule"/>
		<geom conaffinity="0" fromto="-3 -3 0.1 -3 3 0.1" name="sideW" rgba="0.3 0.1 0.3 1" size="0.2" type="capsule"/>
		<body name="shoulder_body" pos="0 0 0">
			<geom conaffinity="0" contype="0" fromto="0 0 0 0 0 0.2" name="shoulder_geom" rgba="0.9 0.4 0.6 1" size="0.18" type="cylinder"/>
			<site name="left_flex_shoulder_insertion" pos="-0.18 0.216 0.1" size="0.025"/>
			<site name="left_flex_shoulder_side" pos="0.0 0.216 0.1" size="0.005"/>
			<site name="right_flex_shoulder_insertion" pos="-0.18 -0.216 0.1" size="0.025"/>
			<site name="right_flex_shoulder_side" pos="0.0 -0.216 0.1" size="0.005"/>
			<body name="upper_arm_body" pos="0 0 .1">
				<geom fromto="0 0 0 1.0 0 0" name="upper_arm_geom" rgba="0.0 0.2 0.4 1" size="0.05" type="capsule"/>
				<joint axis="0 0 1" limited="true" name="shoulder_joint" pos="0 0 0" range="-100 100" type="hinge"/>
				<site name="left_flex_ua_insertion" pos="0.25 0.05 0.0" size="0.025"/>
				<site name="right_flex_ua_insertion" pos="0.25 -0.05 0.0" size="0.025"/>
				<site name="left_curl_ua_insertion" pos="0.5 0.05 0.0" size="0.025"/>
				<site name="right_curl_ua_insertion" pos="0.5 -0.05 0.0" size="0.025"/>
				<body name="elbow_body" pos="1.0 0 0">
					<geom conaffinity="0" contype="0" fromto="0 0 -0.05 0 0 0.05" name="elbow_geom" rgba="0.3 0.9 0.3 0.4" size="0.05500000000000001" type="cylinder"/>
					<site name="elbow_left_side" pos="0 0.06050000000000001 0.0" size="0.005"/>
					<site name="elbow_right_side" pos="0 -0.06050000000000001 0.0" size="0.005"/>
				</body>
				<body name="lower_arm" pos="1 0 0">
					<joint axis="0 0 1" limited="true" name="elbow_joint" pos="0 0 0" range="-172 172" type="hinge"/>
					<geom fromto="0 0 0 1.0 0 0" name="lower_arm_geom" rgba="0.0 0.4 0.6 1" size="0.05" type="capsule"/>
					<site name="left_curl_la_insertion" pos="0.25 0.05 0.0" size="0.025"/>
					<site name="right_curl_la_insertion" pos="0.25 -0.05 0.0" size="0.025"/>
					<body name="fingertip_body" pos="1.1 0 0">
						<geom contype="0" name="fingertip_geom" pos="0 0 0" rgba="0.0 0.8 0.6 1" size=".1" type="sphere"/>
					</body>
				</body>
			</body>
		</body>
		<body name="target_body" pos="0 0 0.1">
			<joint armature="0" axis="1 0 0" damping="0" limited="false" name="target_joint_x" pos="0 0 0" stiffness="0" type="slide"/>
			<joint armature="0" axis="0 1 0" damping="0" limited="false" name="target_joint_y" pos="0 0 0" stiffness="0" type="slide"/>
			<geom conaffinity="0" contype="0" name="target_geom" pos="0 0 0" rgba="0.9 0.2 0.2 1" size=".09" type="sphere"/>
		</body>
	</worldbody>
	<tendon>
		<spatial name="left_flex_tendon" rgba="0.95 0.3 0.3 1" stiffness="100" width="0.02">
			<site site="left_flex_shoulder_insertion"/>
			<geom geom="shoulder_geom" sidesite="left_flex_shoulder_side"/>
			<site site="left_flex_ua_insertion"/>
		</spatial>
		<spatial name="right_flex_tendon" rgba="0.95 0.3 0.3 1" stiffness="100" width="0.02">
			<site site="right_flex_shoulder_insertion"/>
			<geom geom="shoulder_geom" sidesite="right_flex_shoulder_side"/>
			<site site="right_flex_ua_insertion"/>
		</spatial>
		<spatial name="left_curl_tendon" rgba="0.95 0.3 0.3 1" stiffness="100" width="0.02">
			<site site="left_curl_ua_insertion"/>
			<geom geom="elbow_geom" sidesite="elbow_left_side"/>
			<site site="left_curl_la_insertion"/>
		</spatial>
		<spatial name="right_curl_tendon" rgba="0.95 0.3 0.3 1" stiffness="100" width="0.02">
			<site site="right_curl_ua_insertion"/>
			<geom geom="elbow_geom" sidesite="elbow_right_side"/>
			<site site="right_curl_la_insertion"/>
		</spatial>
	</tendon>
	<actuator>
		<general ctrllimited="true" ctrlrange="-1.0 0.0" gainprm="100" name="left_flex_act" tendon="left_flex_tendon"/>
		<general ctrllimited="true" ctrlrange="-1.0 0.0" gainprm="100" name="right_flex_act" tendon="right_flex_tendon"/>
		<general ctrllimited="true" ctrlrange="-1.0 0.0" gainprm="100" name="left_curl_act" tendon="left_curl_tendon"/>
		<general ctrllimited="true" ctrlrange="-1.0 0.0" gainprm="100" name="right_curl_act" tendon="right_curl_tendon"/>
	</actuator>
	<asset>
		<texture fileback="sunny-back.png" filedown="sunny-down.png" filefront="sunny-front.png" fileleft="sunny-left.png" fileright="sunny-right.png" fileup="sunny-up.png" type="skybox"/>
		<texture builtin="flat" height="1278" mark="cross" markrgb="1 1 1" name="texgeom" random="0.01" rgb1="0.8627450980392157 0.8901960784313725 0.9137254901960784" rgb2="0.9058823529411765 0.9215686274509803 0.9647058823529412" type="cube" width="127"/>
		<texture builtin="checker" height="100" name="texplane" rgb1="0.8235294117647058 0.8117647058823529 0.9450980392156862" rgb2="0.43137254901960786 0.6392156862745098 0.9019607843137255" type="2d" width="100"/>
		<material name="MatPlane" reflectance="0.5" shininess="1" specular="1" texrepeat="60 60" texture="texplane"/>
		<material name="geom" texture="texgeom" texuniform="true"/>
	</asset>
</mujoco>