<?xml version="1.0" encoding="utf-8"?>
<mujoco model="reacher">
	<compiler angle="radian" inertiafromgeom="true"/>
	<default>
		<joint armature="1" damping="1" limited="true"/>
		<geom contype="0" friction="1 0.1 0.1" rgba="0.7 0.7 0 1"/>
	</default>
	<option gravity="0 0 -9.81" integrator="RK4" timestep="0.01"/>
	<worldbody>
		<light cutoff="100" diffuse="1 1 1" dir="0 0 -1.3" directional="true" exponent="1" pos="0 0 1.3" specular="0.1 0.1 0.1"/>
		<geom conaffinity="1" condim="3" material="MatPlane" name="floor" pos="0 0 0" rgba="0.8 0.9 0.8 1" size="40 40 40" type="plane"/>
		<geom conaffinity="0" fromto="-3 -3 0.1 3 -3 0.1" name="sideS" rgba="0.3 0.1 0.3 1" size="0.2" type="capsule"/>
		<geom conaffinity="0" fromto="3 -3 0.1 3 3 0.1" name="sideE" rgba="0.3 0.1 0.3 1" size="0.2" type="capsule"/>
		<geom conaffinity="0" fromto="-3 3 0.1 3 3 0.1" name="sideN" rgba="0.3 0.1 0.3 1" size="0.2" type="capsule"/>
		<geom conaffinity="0" fromto="-3 -3 0.1 -3 3 0.1" name="sideW" rgba="0.3 0.1 0.3 1" size="0.2" type="capsule"/>
		<body name="shoulder_body" pos="0 0 0">
			<geom conaffinity="0" contype="0" fromto="0 0 0 0 0 0.2" name="shoulder_geom" rgba="0.9 0.4 0.6 1" size="0.1" type="cylinder"/>
			<site name="left_flex_shoulder_insertion" pos="0.0 0.1 0.1" size="0.05"/>
			<site name="right_flex_shoulder_insertion" pos="0.0 -0.1 0.1" size="0.05"/>
			<body name="upper_arm_body" pos="0 0 .1">
				<geom fromto="0 0 0 1 0 0" name="upper_arm_geom" rgba="0.0 0.4 0.6 1" size=".1" type="capsule"/>
				<joint axis="0 0 1" limited="false" name="shoulder_joint" pos="0 0 0" type="hinge"/>
				<body name="lower_arm" pos="0.1 0 0">
					<joint axis="0 0 1" limited="true" name="elbow_joint" pos="0 0 0" range="-3.0 3.0" type="hinge"/>
					<geom fromto="0 0 0 1 0 0" name="lower_arm_geom" rgba="0.0 0.4 0.6 1" size=".1" type="capsule"/>
					<body name="fingertip_body" pos="0.11 0 0">
						<geom contype="0" name="fingertip_geom" pos="0 0 0" rgba="0.0 0.8 0.6 1" size=".1" type="sphere"/>
					</body>
				</body>
			</body>
		</body>
		<body name="target_body" pos="1 -1 .1">
			<joint armature="0" axis="1 0 0" damping="0" limited="true" name="target_joint_x" pos="0 0 0" range="-.27 .27" ref=".1" stiffness="0" type="slide"/>
			<joint armature="0" axis="0 1 0" damping="0" limited="true" name="target_joint_y" pos="0 0 0" range="-.27 .27" ref="-.1" stiffness="0" type="slide"/>
			<geom conaffinity="0" contype="0" name="target_geom" pos="0 0 0" rgba="0.9 0.2 0.2 1" size=".09" type="sphere"/>
		</body>
	</worldbody>
	<actuator>
		<motor ctrllimited="true" ctrlrange="-1.0 1.0" gear="200.0" joint="shoulder_joint"/>
		<motor ctrllimited="true" ctrlrange="-1.0 1.0" gear="200.0" joint="elbow_joint"/>
	</actuator>
	<asset>
		<texture fileback="sunny-back.png" filedown="sunny-down.png" filefront="sunny-front.png" fileleft="sunny-left.png" fileright="sunny-right.png" fileup="sunny-up.png" type="skybox"/>
		<texture builtin="flat" height="1278" mark="cross" markrgb="1 1 1" name="texgeom" random="0.01" rgb1="0.8627450980392157 0.8901960784313725 0.9137254901960784" rgb2="0.9058823529411765 0.9215686274509803 0.9647058823529412" type="cube" width="127"/>
		<texture builtin="checker" height="100" name="texplane" rgb1="0.8235294117647058 0.8117647058823529 0.9450980392156862" rgb2="0.43137254901960786 0.6392156862745098 0.9019607843137255" type="2d" width="100"/>
		<material name="MatPlane" reflectance="0.5" shininess="1" specular="1" texrepeat="60 60" texture="texplane"/>
		<material name="geom" texture="texgeom" texuniform="true"/>
	</asset>
</mujoco>